<?xml version="1.0" encoding="UTF-8"?>
<!-- Generated by org.testng.reporters.JUnitReportReporter -->
<testsuite hostname="AMALITECH-PC-668" failures="0" tests="3" name="com.elitekaycy.testlabs.labs.MockTest" time="0.978" errors="2" timestamp="2025-06-20T13:54:40 GMT" skipped="0">
  <testcase classname="com.elitekaycy.testlabs.labs.MockTest" name="testGetUserSuccess" time="0.051"/>
  <testcase classname="com.elitekaycy.testlabs.labs.MockTest" name="testGetUserWithWrongEmailThrowsException" time="0.916">
    <error message="
Method MockTest.testGetUserWithWrongEmailThrowsException()[pri:0, instance:com.elitekaycy.testlabs.labs.MockTest@3b938003] should have thrown an exception of type class java.lang.IllegalArgumentException" type="org.testng.TestException">
      <![CDATA[org.testng.TestException: 
Method MockTest.testGetUserWithWrongEmailThrowsException()[pri:0, instance:com.elitekaycy.testlabs.labs.MockTest@3b938003] should have thrown an exception of type class java.lang.IllegalArgumentException
at org.testng.internal.invokers.ExpectedExceptionsHolder.noException(ExpectedExceptionsHolder.java:81)
at org.testng.internal.invokers.TestInvoker.considerExceptionsInternal(TestInvoker.java:895)
at org.testng.internal.invokers.TestInvoker.considerExceptions(TestInvoker.java:860)
at org.testng.internal.invokers.TestInvoker.invokeMethod(TestInvoker.java:741)
at org.testng.internal.invokers.TestInvoker.invokeTestMethod(TestInvoker.java:230)
at org.testng.internal.invokers.MethodRunner.runInSequence(MethodRunner.java:63)
at org.testng.internal.invokers.TestInvoker$MethodInvocationAgent.invoke(TestInvoker.java:992)
at org.testng.internal.invokers.TestInvoker.invokeTestMethods(TestInvoker.java:203)
at org.testng.internal.invokers.TestMethodWorker.invokeTestMethods(TestMethodWorker.java:154)
at org.testng.internal.invokers.TestMethodWorker.run(TestMethodWorker.java:134)
at java.base/java.util.ArrayList.forEach(ArrayList.java:1511)
at org.testng.TestRunner.privateRun(TestRunner.java:739)
at org.testng.TestRunner.run(TestRunner.java:614)
at org.testng.SuiteRunner.runTest(SuiteRunner.java:421)
at org.testng.SuiteRunner.runSequentially(SuiteRunner.java:413)
at org.testng.SuiteRunner.privateRun(SuiteRunner.java:373)
at org.testng.SuiteRunner.run(SuiteRunner.java:312)
at org.testng.SuiteRunnerWorker.runSuite(SuiteRunnerWorker.java:52)
at org.testng.SuiteRunnerWorker.run(SuiteRunnerWorker.java:95)
at org.testng.TestNG.runSuitesSequentially(TestNG.java:1274)
at org.testng.TestNG.runSuitesLocally(TestNG.java:1208)
at org.testng.TestNG.runSuites(TestNG.java:1112)
at org.testng.TestNG.run(TestNG.java:1079)
at org.apache.maven.surefire.testng.TestNGExecutor.run(TestNGExecutor.java:136)
at org.apache.maven.surefire.testng.TestNGDirectoryTestSuite.executeMulti(TestNGDirectoryTestSuite.java:193)
at org.apache.maven.surefire.testng.TestNGDirectoryTestSuite.execute(TestNGDirectoryTestSuite.java:94)
at org.apache.maven.surefire.testng.TestNGProvider.invoke(TestNGProvider.java:145)
at org.apache.maven.surefire.booter.ForkedBooter.runSuitesInProcess(ForkedBooter.java:428)
at org.apache.maven.surefire.booter.ForkedBooter.execute(ForkedBooter.java:162)
at org.apache.maven.surefire.booter.ForkedBooter.run(ForkedBooter.java:562)
at org.apache.maven.surefire.booter.ForkedBooter.main(ForkedBooter.java:548)
]]>
    </error>
  </testcase> <!-- testGetUserWithWrongEmailThrowsException -->
  <testcase classname="com.elitekaycy.testlabs.labs.MockTest" name="testGetUserWithWrongNameThrowsException" time="0.011">
    <error message="
Method MockTest.testGetUserWithWrongNameThrowsException()[pri:0, instance:com.elitekaycy.testlabs.labs.MockTest@3b938003] should have thrown an exception of type class java.lang.IllegalArgumentException" type="org.testng.TestException">
      <![CDATA[org.testng.TestException: 
Method MockTest.testGetUserWithWrongNameThrowsException()[pri:0, instance:com.elitekaycy.testlabs.labs.MockTest@3b938003] should have thrown an exception of type class java.lang.IllegalArgumentException
at org.testng.internal.invokers.ExpectedExceptionsHolder.noException(ExpectedExceptionsHolder.java:81)
at org.testng.internal.invokers.TestInvoker.considerExceptionsInternal(TestInvoker.java:895)
at org.testng.internal.invokers.TestInvoker.considerExceptions(TestInvoker.java:860)
at org.testng.internal.invokers.TestInvoker.invokeMethod(TestInvoker.java:741)
at org.testng.internal.invokers.TestInvoker.invokeTestMethod(TestInvoker.java:230)
at org.testng.internal.invokers.MethodRunner.runInSequence(MethodRunner.java:63)
at org.testng.internal.invokers.TestInvoker$MethodInvocationAgent.invoke(TestInvoker.java:992)
at org.testng.internal.invokers.TestInvoker.invokeTestMethods(TestInvoker.java:203)
at org.testng.internal.invokers.TestMethodWorker.invokeTestMethods(TestMethodWorker.java:154)
at org.testng.internal.invokers.TestMethodWorker.run(TestMethodWorker.java:134)
at java.base/java.util.ArrayList.forEach(ArrayList.java:1511)
at org.testng.TestRunner.privateRun(TestRunner.java:739)
at org.testng.TestRunner.run(TestRunner.java:614)
at org.testng.SuiteRunner.runTest(SuiteRunner.java:421)
at org.testng.SuiteRunner.runSequentially(SuiteRunner.java:413)
at org.testng.SuiteRunner.privateRun(SuiteRunner.java:373)
at org.testng.SuiteRunner.run(SuiteRunner.java:312)
at org.testng.SuiteRunnerWorker.runSuite(SuiteRunnerWorker.java:52)
at org.testng.SuiteRunnerWorker.run(SuiteRunnerWorker.java:95)
at org.testng.TestNG.runSuitesSequentially(TestNG.java:1274)
at org.testng.TestNG.runSuitesLocally(TestNG.java:1208)
at org.testng.TestNG.runSuites(TestNG.java:1112)
at org.testng.TestNG.run(TestNG.java:1079)
at org.apache.maven.surefire.testng.TestNGExecutor.run(TestNGExecutor.java:136)
at org.apache.maven.surefire.testng.TestNGDirectoryTestSuite.executeMulti(TestNGDirectoryTestSuite.java:193)
at org.apache.maven.surefire.testng.TestNGDirectoryTestSuite.execute(TestNGDirectoryTestSuite.java:94)
at org.apache.maven.surefire.testng.TestNGProvider.invoke(TestNGProvider.java:145)
at org.apache.maven.surefire.booter.ForkedBooter.runSuitesInProcess(ForkedBooter.java:428)
at org.apache.maven.surefire.booter.ForkedBooter.execute(ForkedBooter.java:162)
at org.apache.maven.surefire.booter.ForkedBooter.run(ForkedBooter.java:562)
at org.apache.maven.surefire.booter.ForkedBooter.main(ForkedBooter.java:548)
]]>
    </error>
  </testcase> <!-- testGetUserWithWrongNameThrowsException -->
</testsuite> <!-- com.elitekaycy.testlabs.labs.MockTest -->
